def testCatchesCxxExceptionsInTearDown(self):
    self.assert_(('C++ exception with description "Standard C++ exception" thrown in TearDown()' in EX_BINARY_OUTPUT))
    self.assert_(('CxxExceptionInTearDownTest::TearDownTestCase() called as expected.' in EX_BINARY_OUTPUT))
    self.assert_(('CxxExceptionInTearDownTest destructor called as expected.' in EX_BINARY_OUTPUT))
