def testCatchesCxxExceptionsInFixtureConstructor(self):
    self.assert_(('C++ exception with description "Standard C++ exception" thrown in the test fixture\'s constructor' in EX_BINARY_OUTPUT))
    self.assert_(('unexpected' not in EX_BINARY_OUTPUT), 'This failure belongs in this test only if "CxxExceptionInConstructorTest" (no quotes) appears on the same line as words "called unexpectedly"')
